File: Lab 1: Tensile Testing/Cast_Group7
%	Crosshead Position (in)	Load (lbs)	Extensometer Position (in)	6/28/2017	1:19 PM
0.00076784	51.01250458	-0.01121731
0.00126004	110.60212708	-0.01116689
0.00175718	160.70211792	-0.01113634
0.00225186	201.46253967	-0.01110089
0.00275148	226.41806030	-0.01109345
0.00325601	244.44195557	-0.01108032
0.00375806	260.86859131	-0.01107858
0.00425764	272.80502319	-0.01109938
0.00475726	286.53833008	-0.01110144
0.00525684	299.72357178	-0.01109707
0.00575894	310.01721191	-0.01110646
0.00626342	321.45648193	-0.01110038
0.00676057	332.68408203	-0.01110548
0.00725524	341.59350586	-0.01110046
0.00775239	351.34042358	-0.01110527
0.00825692	362.91503906	-0.01110020
0.00876145	371.54443359	-0.01110727
0.00925859	380.08401489	-0.01111147
0.00975079	390.00378418	-0.01110491
0.01025284	396.71835327	-0.01110896
0.01075490	408.83834839	-0.01109664
0.01125942	419.91986084	-0.01109426
0.01175657	427.75598145	-0.01108763
0.01225620	438.45159912	-0.01108737
0.01275577	449.00515747	-0.01109117
0.01325783	459.32559204	-0.01108713
0.01376235	470.85464478	-0.01108004
0.01425950	481.96697998	-0.01107854
0.01475418	491.12567139	-0.01106477
0.01525132	502.85705566	-0.01107480
0.01575338	515.17401123	-0.01107299
0.01626281	525.34167480	-0.01108053
0.01675753	538.71051025	-0.01106875
0.01725220	551.97619629	-0.01107055
0.01775178	563.67272949	-0.01107159
0.01825631	577.41009521	-0.01107576
0.01876083	591.35241699	-0.01106381
0.01925551	602.77832031	-0.01105222
0.01975508	615.61785889	-0.01105238
0.02025718	620.40020752	-0.01105614
0.02075924	638.86358643	-0.01104318
0.02126129	654.08294678	-0.01104648
0.02175844	669.30627441	-0.01103251
0.02225558	682.21282959	-0.01102754
0.02275269	697.01007080	-0.01102129
0.02325479	712.34197998	-0.01102194
0.02375931	723.06976318	-0.01101306
0.02425889	738.65356445	-0.01101533
0.02475109	753.07830811	-0.01101059
0.02525071	766.90808105	-0.01100254
0.02575772	779.25317383	-0.01100610
0.02625729	798.23382568	-0.01100220
0.02675692	812.57946777	-0.01098597
0.02725402	828.12445068	-0.01098245
0.02775855	841.88317871	-0.01099181
0.02825817	857.24188232	-0.01096655
0.02876270	873.58947754	-0.01097496
0.02925980	889.62481689	-0.01096731
0.02975447	900.46783447	-0.01095137
0.03025162	917.19464111	-0.01094024
0.03075367	935.54412842	-0.01094794
0.03126315	945.67559814	-0.01094571
0.03176030	964.19793701	-0.01094741
0.03225250	980.46649170	-0.01093414
0.03275207	995.28918457	-0.01093058
0.03325417	1008.65264893	-0.01092178
0.03376113	1027.03564453	-0.01091565
0.03425580	1042.39843750	-0.01092735
0.03475543	1056.38220215	-0.01091288
0.03525748	1073.39843750	-0.01090583
0.03575953	1089.78625488	-0.01090838
0.03626158	1107.86242676	-0.01090634
0.03675873	1120.61352539	-0.01089562
0.03725588	1126.89392090	-0.01090026
0.03775303	1147.93811035	-0.01089065
0.03825508	1164.39562988	-0.01088168
0.03875961	1177.11047363	-0.01088837
0.03925919	1201.70556641	-0.01087119
0.03975143	1218.03710937	-0.01086675
0.04025101	1232.17370605	-0.01086165
0.04075554	1248.50927734	-0.01084819
0.04126006	1268.82043457	-0.01084179
0.04175721	1291.42163086	-0.01082662
0.04225679	1305.45373535	-0.01082876
0.04275642	1323.97753906	-0.01081753
0.04326094	1343.92956543	-0.01080225
0.04376052	1364.04248047	-0.01080008
0.04426014	1383.44653320	-0.01078080
0.04475482	1400.50561523	-0.01077537
0.04525197	1420.81018066	-0.01076078
0.04575649	1441.60644531	-0.01076384
0.04625855	1460.05773926	-0.01074621
0.04676307	1479.77136230	-0.01077637
0.04725037	1499.67651367	-0.01072744
0.04774994	1518.32885742	-0.01071830
0.04825694	1539.01794434	-0.01070642
0.04875900	1547.17700195	-0.01071052
0.04925858	1567.30859375	-0.01070620
0.04975325	1586.00512695	-0.01071088
0.05025778	1616.15307617	-0.01068485
0.05075987	1631.69799805	-0.01068050
0.05126193	1651.12219238	-0.01067062
0.05175908	1680.79162598	-0.01065482
0.05225375	1695.09582520	-0.01064983
0.05275333	1713.75219727	-0.01063667
0.05325295	1740.42285156	-0.01062715
0.05375991	1760.17932129	-0.01061548
0.05425953	1776.95703125	-0.01061192
0.05475173	1806.48718262	-0.01059109
0.05525135	1822.55737305	-0.01058918
0.05575341	1841.46301270	-0.01058006
0.05626036	1871.96459961	-0.01057124
0.05675508	1887.73193359	-0.01055597
0.05725713	1911.54455566	-0.01054403
0.05775919	1927.90014648	-0.01052874
0.05825876	1957.49865723	-0.01051982
0.05876329	1977.63830566	-0.01051193
0.05926044	1999.55346680	-0.01050223
0.05975511	2017.06689453	-0.01049505
0.06025226	2038.32409668	-0.01047738
0.06075184	2062.56665039	-0.01046559
0.06126132	2084.56884766	-0.01045744
0.06175847	2106.87402344	-0.01045036
0.06225314	2128.73144531	-0.01044725
0.06275024	2149.33081055	-0.01042913
0.06325725	2173.26806641	-0.01041687
0.06375930	2195.40161133	-0.01040399
0.06425644	2217.74560547	-0.01038967
0.06475607	2240.12963867	-0.01037665
0.06525812	2262.61035156	-0.01036867
0.06576017	2284.52124023	-0.01035003
0.06625975	2306.83837891	-0.01033342
0.06676185	2330.24365234	-0.01032260
0.06725653	2350.91406250	-0.01030909
0.06775120	2373.19506836	-0.01029655
0.06825325	2396.58544922	-0.01027916
0.06876025	2419.07397461	-0.01026399
0.06925983	2441.81738281	-0.01024292
0.06975203	2463.44702148	-0.01022202
0.07025165	2485.06591797	-0.01020855
0.07075866	2508.64819336	-0.01019306
0.07125823	2532.30664062	-0.01017639
0.07176028	2553.02099609	-0.01015499
0.07225496	2576.38208008	-0.01013583
0.07275706	2599.38110352	-0.01011518
0.07325911	2620.35839844	-0.01009554
0.07376364	2643.19409180	-0.01007347
0.07426074	2665.44555664	-0.01004729
0.07475546	2685.87866211	-0.01002488
0.07525256	2707.68115234	-0.00999595
0.07575218	2730.00366211	-0.00997007
0.07625914	2751.77294922	-0.00994395
0.07675876	2774.36743164	-0.00992192
0.07725096	2795.33911133	-0.00989056
0.07775059	2815.02197266	-0.00985266
0.07825511	2837.48242187	-0.00981815
0.07875964	2859.78222656	-0.00977990
0.07925674	2878.46118164	-0.00973700
0.07975389	2899.72509766	-0.00969747
0.08025842	2920.91943359	-0.00965619
0.08075804	2940.53125000	-0.00960723
0.08126252	2961.59814453	-0.00955781
0.08175967	2982.07543945	-0.00950487
0.08225682	2999.94262695	-0.00944808
0.08275150	3019.03833008	-0.00940372
0.08325355	3039.16333008	-0.00933839
0.08376055	3057.71533203	-0.00927877
0.08426013	3077.58422852	-0.00921670
0.08475237	3094.99853516	-0.00914538
0.08524705	3112.00122070	-0.00907798
0.08575647	3131.91040039	-0.00900795
0.08626100	3150.88842773	-0.00892991
0.08675815	3167.21191406	-0.00885579
0.08725773	3184.40087891	-0.00877176
0.08775736	3201.41308594	-0.00869136
0.08825941	3217.70190430	-0.00860576
0.08876146	3233.79882812	-0.00851254
0.08926108	3251.57080078	-0.00841968
0.08975575	3264.57104492	-0.00832386
0.09025043	3279.50781250	-0.00822219
0.09075496	3295.38891602	-0.00811933
0.09125949	3309.98266602	-0.00799936
0.09196086	-2.94390535	-0.00266312
0.09187227	-1.72855628	-0.00220594