File: Lab 1: Tensile Testing/Cast_Group2
%	Crosshead Position (in)	Load (lbs)	Extensometer Position (in)	6/27/2017	1:42 PM
0.00292129	1.35336518	-0.00391696
0.00783113	244.36155701	-0.00390081
0.01283208	313.18487549	-0.00388205
0.01783547	420.57376099	-0.00385459
0.02282900	539.43011475	-0.00378622
0.02782995	673.80456543	-0.00372088
0.03283086	830.14105225	-0.00364499
0.03782934	989.17761230	-0.00356351
0.04283025	1168.45031738	-0.00346905
0.04783611	1369.55908203	-0.00335406
0.05282964	1575.94873047	-0.00322746
0.05783059	1792.19909668	-0.00310369
0.06283151	2011.18566895	-0.00295280
0.06782998	2226.64282227	-0.00274493
0.07283089	2435.21118164	-0.00236551
0.07783675	2627.22167969	-0.00177744
0.08283028	2794.05957031	-0.00095581
0.08783119	2938.30541992	0.00002885
0.09283462	3063.89257812	0.00113656
0.09720304	-1.98449004	-0.00265414
0.09709721	-1.08939278	-0.00272377