File: Lab 1: Tensile Testing/Ductile_Group2
%	Crosshead Position (in)	Load (lbs)	Extensometer Position (in)	6/27/2017	1:49 PM
0.00153815	11.31735229	-0.00297917
0.00644061	289.60952759	-0.00291263
0.01143661	381.81658936	-0.00292155
0.01644247	469.59375000	-0.00279984
0.02144091	575.78741455	-0.00257105
0.02643691	704.54473877	-0.00242645
0.03144030	852.59356689	-0.00231363
0.03644120	1018.47326660	-0.00217876
0.04143478	1204.96972656	-0.00204203
0.04644059	1405.66577148	-0.00191520
0.05143907	1591.66381836	-0.00175901
0.05643751	1824.31274414	-0.00162324
0.06144337	2061.37817383	-0.00143985
0.06643937	2305.37524414	-0.00127119
0.07143538	2558.85253906	-0.00111122
0.07643876	2819.06860352	-0.00095370
0.08143967	3082.67749023	-0.00081310
0.08643568	3351.85522461	-0.00065908
0.09144148	3626.57910156	-0.00049041
0.09644239	3899.22851562	-0.00028941
0.10143597	4168.44775391	-0.00001673
0.10644425	4425.10742187	0.00038138
0.11144026	4641.32324219	0.00097664
0.11643627	4771.92285156	0.00206243
0.12144455	4843.22509766	0.00366484
0.12644298	4882.61474609	0.00573842
0.13143657	4911.82470703	0.00807685
0.13643995	4933.71044922	0.01063398
0.14143838	4951.39648437	0.01340745
0.14643930	4967.29687500	0.01621649
0.15144515	4983.12158203	0.01904035
0.15644358	4995.98535156	0.02184263
0.16143715	5010.07763672	0.02455360
0.16644050	5023.16650391	0.02721056
0.17143898	5034.38720703	0.02965331
0.17643745	5047.27539062	0.03201723
0.18144327	5059.33349609	0.03458874
0.18644175	5069.71289062	0.03719012
0.19143775	5080.86132812	0.03975745
0.19644110	5091.68017578	0.04230082
0.20143710	5100.91015625	0.04472871
0.20643310	5109.09033203	0.04725207
0.21144140	5120.57958984	0.04971389
0.21644235	5125.81347656	0.05235513
0.22143835	5134.74169922	0.05507855
0.22644417	5142.72363281	0.05785762
0.23144017	5148.27246094	0.06065507
0.23643617	5153.45556641	0.06350841
0.24144198	5160.15136719	0.06639232
0.24644294	5164.02783203	0.06936596
0.25143895	5167.70312500	0.07236676
0.25644228	5172.32910156	0.07548399
0.26144075	5173.34863281	0.07866801
0.26643676	5175.68701172	0.08195265
0.27144259	5178.35986328	0.08530013
0.27644107	5176.89697266	0.08873035
0.28143954	5175.94824219	0.09225525
0.28644288	5174.99951172	0.09588443
0.29143888	5170.31738281	0.09962617
0.29643488	5166.58984375	0.10344546
0.30144075	5162.31933594	0.10736708
0.30643919	5153.13769531	0.11138709
0.31144014	5142.59228516	0.11550362
0.31644595	5133.59570312	0.11973248
0.32144195	5118.23046875	0.12396280
0.32643548	5102.38525391	0.12835746
0.33144134	5084.90429687	0.13289560
0.33643979	5064.79150391	0.13752379
0.34143826	5041.09814453	0.14215009
0.34644163	5016.69970703	0.14697827
0.35144255	4987.86767578	0.15187253
0.35643607	4957.11572266	0.15684126
0.36143947	4925.65332031	0.16185965
0.36643794	4887.97460937	0.16693060
0.37143639	4847.18994141	0.17204063
0.37644467	4806.28613281	0.17718972
0.38144314	4756.64746094	0.18238287
0.38643914	4703.83007812	0.18763490
0.39144006	4647.36230469	0.19290586
0.39643854	4580.89453125	0.19825993
0.40143698	4502.37158203	0.20370041
0.40644526	4372.95898437	0.20940964
0.40893096	-3.21457815	0.30190891
0.40893096	-2.58479428	0.30189139