File: Lab 1: Tensile Testing/Ductile_Group7
%	Crosshead Position (in)	Load (lbs)	Extensometer Position (in)	6/28/2017	1:41 PM
0.00599521	33.39731216	-0.00185351
0.01084106	190.02726746	-0.00202443
0.01584449	215.64340210	-0.00206074
0.02084293	267.54162598	-0.00211187
0.02583898	330.40344238	-0.00214836
0.03084236	409.10098267	-0.00213483
0.03584327	503.93438721	-0.00202173
0.04084175	619.86560059	-0.00187847
0.04584513	757.66497803	-0.00171649
0.05084118	913.30340576	-0.00156604
0.05583719	1082.79699707	-0.00160287
0.06084548	1269.72900391	-0.00161663
0.06584395	1463.59790039	-0.00151660
0.07083996	1683.86157227	-0.00137542
0.07584339	1914.67871094	-0.00122927
0.08083940	2153.04394531	-0.00107512
0.08583540	2398.89404297	-0.00090256
0.09084368	2654.29565430	-0.00074388
0.09583974	2914.69921875	-0.00055417
0.10084065	3179.92553711	-0.00036423
0.10584403	3454.56347656	-0.00016335
0.11084251	3732.61181641	0.00004105
0.11583608	4013.10156250	0.00026044
0.12083947	4301.45556641	0.00051744
0.12584038	4584.59570312	0.00079501
0.13084133	4859.46289062	0.00112562
0.13584472	5123.35058594	0.00153491
0.14084320	5361.48632812	0.00208387
0.14583677	5515.78369141	0.00337322
0.15084507	5566.99316406	0.00573923
0.15584354	5588.14599609	0.00837240
0.16084202	5602.52783203	0.01115586
0.16584541	5619.90039062	0.01398452
0.17084388	5634.77929687	0.01667854
0.17583741	5650.92041016	0.01918246
0.18084328	5668.83593750	0.02157286
0.18584175	5684.73730469	0.02392709
0.19084023	5700.64648437	0.02628027
0.19584610	5719.47167969	0.02862750
0.20084457	5734.85595703	0.03093986
0.20584057	5749.16943359	0.03323749
0.21084397	5766.12695312	0.03552125
0.21584244	5782.01220703	0.03781052
0.22083844	5795.18652344	0.04011665
0.22584431	5810.47558594	0.04243344
0.23084278	5825.01562500	0.04476243
0.23583879	5836.42285156	0.04708198
0.24084218	5850.52734375	0.04942372
0.24583822	5862.90429687	0.05178013
0.25083667	5871.28173828	0.05417019
0.25584251	5884.14843750	0.05654788
0.26084346	5893.05761719	0.05896923
0.26584196	5901.17529297	0.06140581
0.27084532	5909.71337891	0.06388882
0.27584133	5917.93017578	0.06638053
0.28083983	5923.61279297	0.06891209
0.28584567	5929.89208984	0.07149014
0.29084414	5934.91308594	0.07409254
0.29584017	5937.85693359	0.07673234
0.30084601	5942.70605469	0.07944530
0.30583954	5944.99609375	0.08215916
0.31083804	5947.28076172	0.08497691
0.31584388	5950.20458984	0.08784211
0.32084236	5950.65625000	0.09079355
0.32584086	5948.13720703	0.09380117
0.33084670	5949.37646484	0.09689516
0.33584270	5945.81640625	0.10003075
0.34083873	5939.69921875	0.10325563
0.34584209	5934.79785156	0.10651878
0.35084304	5924.38476562	0.10981902
0.35584155	5908.97656250	0.11312827
0.36084735	5892.62207031	0.11644575
0.36584339	5871.01806641	0.11978126
0.37083942	5843.49902344	0.12314847
0.37584278	5815.46142578	0.12650022
0.38084126	5781.19482422	0.12993136
0.38583729	5741.47656250	0.13340867
0.39084560	5702.52539062	0.13694537
0.39584160	5656.90869141	0.14053318
0.40084010	5604.69042969	0.14423281
0.40584347	5551.65429687	0.14800280
0.41083947	5493.05761719	0.15185443
0.41584045	5429.64501953	0.15581754
0.42084381	5361.34326172	0.15988788
0.42584473	5288.42333984	0.16408485
0.43084073	5205.42480469	0.16838872
0.43584168	5118.77978516	0.17283648
0.44084015	5023.69433594	0.17738879
0.44583866	4917.78515625	0.18218488
0.45098722	9.48829937	0.19496471
0.45080018	-2.24578238	0.18583810